Workbook

Sheet Raw Data
A1: cust | B1: Name | C1: Age | D1: Gender | E1: marital stat | F1: Pur Date | G1: Amt | H1: Location
A2: C712 | B2: Elizabeth Evans | C2: twenty | D2: M | E2: Single | F2: 30-08-1980 | G2: 9500 | H2: south africa
A3: C710 | B3: michelle carter | D3: F | E3: Single | F3: 43902 | G3: 5512.8264 | H3: lagos
A4: C660 | B4: orge sullivan | C4: twenty | D4: F | E4: Single | F4: 45346 | G4: 123000 | H4: lagos
A5: C256 | B5: Jennifer Silva | C5: 61 | D5: Male | E5: Marrd | F5: 29-07-1976 | G5: 25000 | H5: lagos
A6: C877 | B6: Debbie Trujillo | C6: 59 | D6: Female | E6: Sungle | F6: 40567 | G6: 430 | H6: south africa
A7: C101 | B7: Hector Bowen | C7: twenty | D7: M | E7: Marrd | F7: 45470 | G7: 9389.905 | H7: lagos
A8: C617 | B8: Margaret Chapman | D8: Female | E8: Marrd | F8: 43665 | G8: 9500 | H8: india
A9: C018 | B9: aaron gardner | C9: twenty | D9: Male | E9: Marrd | F9: 43719 | G9: 1500 | H9: spain
A10: C920 | B10: Jennifer Brown | C10: 38 | D10: Female | E10: Sungle | F10: 40438 | G10: 1700 | H10: lagos
A11: C422 | B11: Katie Mays | C11: twenty | D11: Female | E11: Single | F11: 36839 | G11: 45000
A12: C586 | B12: Jill Hudson | D12: Male | E12: Sungle | F12: 45526 | G12: 9500 | H12: india
A13: C927 | B13: Victor Brown | C13: twenty | D13: M | E13: Marrd | F13: 45492 | G13: 9821.6898
A14: C704 | B14: James Graham | C14: 51 | D14: Male | E14: Marrd | F14: 43540 | G14: 2500 | H14: south africa
A15: C081 | B15: Danielle Mckinney | C15: twenty | D15: M | E15: Sungle | F15: 17-08-2002 | G15: 29370 | H15: india
A16: C868 | B16: ROBERT ATKINSON | C16: twenty | D16: Female | E16: Single | F16: 37804 | G16: 242.10716 | H16: spain
A17: C565 | B17: Monica Reyes | D17: Male | E17: Single | F17: 45334 | G17: 4148.4603 | H17: south africa
A18: C952 | B18: Steven Wiley | C18: twenty | D18: Female | E18: Marrd | F18: 44037 | G18: 8326.3703 | H18: south africa
A19: C528 | B19: Caitlyn Maxwell | C19: twenty | D19: M | E19: Single | F19: 44369 | G19: 9500 | H19: india
A20: C859 | B20: Ashley Mcgee | C20: twenty | D20: Male | E20: Marrd | F20: 19-02-2013 | G20: 1500 | H20: south africa
A21: C464 | B21: Lisa Jimenez | C21: 32 | D21: Female | E21: Marrd | F21: 37736 | G21: 9600 | H21: spain
A22: C658 | B22: Megan Brown | C22: 46 | D22: Female | E22: Single | F22: 45390 | G22: 9500 | H22: south africa
A23: C164 | B23: Glen Bell | D23: F | E23: Single | F23: 43599 | G23: 1500
A24: C141 | B24: Melissa Flynn | C24: twenty | D24: M | E24: Marrd | F24: 44166 | G24: 8846.8605 | H24: india
A25: C829 | B25: SCOTT BEARD | C25: 47 | D25: F | E25: Sungle | F25: 16-01-1973 | G25: 23000 | H25: south africa
A26: C373 | B26: Brian Andrade | C26: twenty | D26: Male | E26: Single | F26: 45494 | G26: 5261.0191
A27: C679 | B27: Paul Hughes | C27: twenty | D27: M | E27: Single | F27: 45278 | G27: 1500 | H27: south africa
A28: C292 | B28: Julia Ochoa | C28: 58 | D28: Female | E28: Sungle | F28: 43735 | G28: 899.65042 | H28: lagos
A29: C712 | B29: Elizabeth Evans | C29: twenty | D29: M | E29: Single | F29: 30-08-1980 | G29: 9500 | H29: south africa
A30: C710 | B30: michelle carter | D30: F | E30: Single | F30: 43902 | G30: 5512.8264 | H30: lagos
A31: C754 | B31: Amber Carson | C31: 26 | D31: FEMale | E31: Marrd | F31: 43506 | G31: 1500 | H31: lagos
A32: C754 | B32: Amber Carson | D32: Female | E32: Marrd | F32: 38148 | G32: 1500
A33: C668 | B33: Thomas Morris | C33: twenty | D33: Male | E33: Marrd | F33: 44033 | G33: 9500 | H33: india
A34: C267 | B34: Gregory Weber | C34: twenty | D34: F | E34: Marrd | F34: 44875 | G34: 356.91702
A35: C240 | B35: joshua oconnor | C35: 39 | D35: Female | E35: Marrd | F35: 22-06-1993 | G35: 9500
A36: C516 | B36: Heather Carlson | C36: twenty | D36: M | E36: Single | F36: 31511 | G36: 1000 | H36: lagos
A37: C251 | B37: JEREMIAH MUNOZ | C37: 41 | D37: F | E37: Marrd | F37: 44058 | G37: 1500 | H37: spain
A38: C061 | B38: Nicholas White | C38: 34 | D38: Male | E38: Single | F38: 43415 | G38: 9500
A39: C067 | B39: Maria George | D39: Female | E39: Sungle | F39: 45562 | G39: 5000 | H39: spain
A40: C645 | B40: Jeremy Wood | D40: F | E40: Marrd | F40: 43506 | G40: 9500 | H40: lagos
...

Sheet Cleaned Data
A1: Customer | B1: Name | C1: Age | D1: Gender | E1: Marital Status | F1: Purchase Date | G1: Purchase Date (Day) | H1: Purchase Date(Month) | I1: Amount | J1: Amount Status | K1: Location | L1: Transaction Identification | M1: Customer Location Using Customer ID
A2: C712 | B2: Elizabeth Evans | C2: 20 | D2: Male | E2: Single | F2: 29463 | G2: =TEXT(F2,"DDDD") -> Saturday | H2: =TEXT(F2,"MMMM") -> August | I2: 9500 | J2: =IF(LEN(TRIM(I2))=0,"Not Recorded","Recorded") -> Recorded | K2: South Africa | L2: =IF(I2>10000,"High value","Regular") -> Regular | M2: =_xlfn.XLOOKUP(A2,A:A,K:K,"Not Provided",0) -> South Africa
A3: C710 | B3: Michelle Carter | C3: 30 | D3: Female | E3: Single | F3: 44168 | G3: =TEXT(F3,"DDDD") -> Thursday | H3: =TEXT(F3,"MMMM") -> December | I3: 5512.8264 | J3: =IF(LEN(TRIM(I3))=0,"Not Recorded","Recorded") -> Recorded | K3: Lagos | L3: =IF(I3>10000,"High value","Regular") -> Regular | M3: =_xlfn.XLOOKUP(A3,A:A,K:K,"Not Provided",0) -> Lagos
A4: C660 | B4: Orge Sullivan | C4: 20 | D4: Female | E4: Single | F4: 45346 | G4: =TEXT(F4,"DDDD") -> Saturday | H4: =TEXT(F4,"MMMM") -> February | I4: 123000 | J4: =IF(LEN(TRIM(I4))=0,"Not Recorded","Recorded") -> Recorded | K4: Lagos | L4: =IF(I4>10000,"High value","Regular") -> High value | M4: =_xlfn.XLOOKUP(A4,A:A,K:K,"Not Provided",0) -> Lagos
A5: C256 | B5: Jennifer Silva | C5: 61 | D5: Male | E5: Married | F5: 27970 | G5: =TEXT(F5,"DDDD") -> Thursday | H5: =TEXT(F5,"MMMM") -> July | I5: 25000 | J5: =IF(LEN(TRIM(I5))=0,"Not Recorded","Recorded") -> Recorded | K5: Lagos | L5: =IF(I5>10000,"High value","Regular") -> High value | M5: =_xlfn.XLOOKUP(A5,A:A,K:K,"Not Provided",0) -> Lagos
A6: C877 | B6: Debbie Trujillo | C6: 59 | D6: Female | E6: Single | F6: 40567 | G6: =TEXT(F6,"DDDD") -> Monday | H6: =TEXT(F6,"MMMM") -> January | I6: 430 | J6: =IF(LEN(TRIM(I6))=0,"Not Recorded","Recorded") -> Recorded | K6: South Africa | L6: =IF(I6>10000,"High value","Regular") -> Regular | M6: =_xlfn.XLOOKUP(A6,A:A,K:K,"Not Provided",0) -> South Africa
A7: C101 | B7: Hector Bowen | C7: 20 | D7: Male | E7: Married | F7: 45470 | G7: =TEXT(F7,"DDDD") -> Thursday | H7: =TEXT(F7,"MMMM") -> June | I7: 9389.905 | J7: =IF(LEN(TRIM(I7))=0,"Not Recorded","Recorded") -> Recorded | K7: Lagos | L7: =IF(I7>10000,"High value","Regular") -> Regular | M7: =_xlfn.XLOOKUP(A7,A:A,K:K,"Not Provided",0) -> Lagos | T7: Regular | U7: =COUNTIF(L:L,T7) -> 457
A8: C617 | B8: Margaret Chapman | C8: 30 | D8: Female | E8: Married | F8: 43665 | G8: =TEXT(F8,"DDDD") -> Friday | H8: =TEXT(F8,"MMMM") -> July | I8: 9500 | J8: =IF(LEN(TRIM(I8))=0,"Not Recorded","Recorded") -> Recorded | K8: India | L8: =IF(I8>10000,"High value","Regular") -> Regular | M8: =_xlfn.XLOOKUP(A8,A:A,K:K,"Not Provided",0) -> India | T8: High value | U8: =COUNTIF(L:L,T8) -> 24
A9: C018 | B9: Aaron Gardner | C9: 20 | D9: Male | E9: Married | F9: 43778 | G9: =TEXT(F9,"DDDD") -> Saturday | H9: =TEXT(F9,"MMMM") -> November | I9: 1500 | J9: =IF(LEN(TRIM(I9))=0,"Not Recorded","Recorded") -> Recorded | K9: Spain | L9: =IF(I9>10000,"High value","Regular") -> Regular | M9: =_xlfn.XLOOKUP(A9,A:A,K:K,"Not Provided",0) -> Spain
A10: C920 | B10: Jennifer Brown | C10: 38 | D10: Female | E10: Single | F10: 40438 | G10: =TEXT(F10,"DDDD") -> Friday | H10: =TEXT(F10,"MMMM") -> September | I10: 1700 | J10: =IF(LEN(TRIM(I10))=0,"Not Recorded","Recorded") -> Recorded | K10: Lagos | L10: =IF(I10>10000,"High value","Regular") -> Regular | M10: =_xlfn.XLOOKUP(A10,A:A,K:K,"Not Provided",0) -> Lagos
A11: C422 | B11: Katie Mays | C11: 20 | D11: Female | E11: Single | F11: 36780 | G11: =TEXT(F11,"DDDD") -> Monday | H11: =TEXT(F11,"MMMM") -> September | I11: 45000 | J11: =IF(LEN(TRIM(I11))=0,"Not Recorded","Recorded") -> Recorded | K11: Not Provided | L11: =IF(I11>10000,"High value","Regular") -> High value | M11: =_xlfn.XLOOKUP(A11,A:A,K:K,"Not Provided",0) -> Not Provided
A12: C586 | B12: Jill Hudson | C12: 30 | D12: Male | E12: Single | F12: 45526 | G12: =TEXT(F12,"DDDD") -> Thursday | H12: =TEXT(F12,"MMMM") -> August | I12: 9500 | J12: =IF(LEN(TRIM(I12))=0,"Not Recorded","Recorded") -> Recorded | K12: India | L12: =IF(I12>10000,"High value","Regular") -> Regular | M12: =_xlfn.XLOOKUP(A12,A:A,K:K,"Not Provided",0) -> India
A13: C927 | B13: Victor Brown | C13: 20 | D13: Male | E13: Married | F13: 45492 | G13: =TEXT(F13,"DDDD") -> Friday | H13: =TEXT(F13,"MMMM") -> July | I13: 9821.6898 | J13: =IF(LEN(TRIM(I13))=0,"Not Recorded","Recorded") -> Recorded | K13: Not Provided | L13: =IF(I13>10000,"High value","Regular") -> Regular | M13: =_xlfn.XLOOKUP(A13,A:A,K:K,"Not Provided",0) -> Not Provided
A14: C704 | B14: James Graham | C14: 51 | D14: Male | E14: Married | F14: 43540 | G14: =TEXT(F14,"DDDD") -> Saturday | H14: =TEXT(F14,"MMMM") -> March | I14: 2500 | J14: =IF(LEN(TRIM(I14))=0,"Not Recorded","Recorded") -> Recorded | K14: South Africa | L14: =IF(I14>10000,"High value","Regular") -> Regular | M14: =_xlfn.XLOOKUP(A14,A:A,K:K,"Not Provided",0) -> South Africa
A15: C081 | B15: Danielle Mckinney | C15: 20 | D15: Male | E15: Single | F15: 37485 | G15: =TEXT(F15,"DDDD") -> Saturday | H15: =TEXT(F15,"MMMM") -> August | I15: 29370 | J15: =IF(LEN(TRIM(I15))=0,"Not Recorded","Recorded") -> Recorded | K15: India | L15: =IF(I15>10000,"High value","Regular") -> High value | M15: =_xlfn.XLOOKUP(A15,A:A,K:K,"Not Provided",0) -> India
A16: C868 | B16: Robert Atkinson | C16: 20 | D16: Female | E16: Single | F16: 37659 | G16: =TEXT(F16,"DDDD") -> Friday | H16: =TEXT(F16,"MMMM") -> February | I16: 242.10716 | J16: =IF(LEN(TRIM(I16))=0,"Not Recorded","Recorded") -> Recorded | K16: Spain | L16: =IF(I16>10000,"High value","Regular") -> Regular | M16: =_xlfn.XLOOKUP(A16,A:A,K:K,"Not Provided",0) -> Spain
A17: C565 | B17: Monica Reyes | C17: 30 | D17: Male | E17: Single | F17: 45628 | G17: =TEXT(F17,"DDDD") -> Monday | H17: =TEXT(F17,"MMMM") -> December | I17: 4148.4603 | J17: =IF(LEN(TRIM(I17))=0,"Not Recorded","Recorded") -> Recorded | K17: South Africa | L17: =IF(I17>10000,"High value","Regular") -> Regular | M17: =_xlfn.XLOOKUP(A17,A:A,K:K,"Not Provided",0) -> South Africa
A18: C952 | B18: Steven Wiley | C18: 20 | D18: Female | E18: Married | F18: 44037 | G18: =TEXT(F18,"DDDD") -> Saturday | H18: =TEXT(F18,"MMMM") -> July | I18: 8326.3703 | J18: =IF(LEN(TRIM(I18))=0,"Not Recorded","Recorded") -> Recorded | K18: South Africa | L18: =IF(I18>10000,"High value","Regular") -> Regular | M18: =_xlfn.XLOOKUP(A18,A:A,K:K,"Not Provided",0) -> South Africa
A19: C528 | B19: Caitlyn Maxwell | C19: 20 | D19: Male | E19: Single | F19: 44369 | G19: =TEXT(F19,"DDDD") -> Tuesday | H19: =TEXT(F19,"MMMM") -> June | I19: 9500 | J19: =IF(LEN(TRIM(I19))=0,"Not Recorded","Recorded") -> Recorded | K19: India | L19: =IF(I19>10000,"High value","Regular") -> Regular | M19: =_xlfn.XLOOKUP(A19,A:A,K:K,"Not Provided",0) -> India
A20: C859 | B20: Ashley Mcgee | C20: 20 | D20: Male | E20: Married | F20: 41324 | G20: =TEXT(F20,"DDDD") -> Tuesday | H20: =TEXT(F20,"MMMM") -> February | I20: 1500 | J20: =IF(LEN(TRIM(I20))=0,"Not Recorded","Recorded") -> Recorded | K20: South Africa | L20: =IF(I20>10000,"High value","Regular") -> Regular | M20: =_xlfn.XLOOKUP(A20,A:A,K:K,"Not Provided",0) -> South Africa
... A204: C498 | B204: Joshua Perry | C204: 20 | D204: Male | E204: Single | F204: 45414 | G204: =TEXT(F204,"DDDD") -> Thursday | H204: =TEXT(F204,"MMMM") -> May | I204: 9500 | J204: =IF(LEN(TRIM(I204))=0,"Not Recorded","Recorded") -> Recorded | K204: South Africa | L204: =IF(I204>10000,"High value","Regular") -> Regular | M204: =_xlfn.XLOOKUP(A204,A:A,K:K,"Not Provided",0) -> Spain
A205: C498 | B205: Joshua Perry | C205: 30 | D205: Male | E205: Single | F205: 45414 | G205: =TEXT(F205,"DDDD") -> Thursday | H205: =TEXT(F205,"MMMM") -> May | J205: =IF(LEN(TRIM(I205))=0,"Not Recorded","Recorded") -> Not Recorded | K205: Not Provided | L205: =IF(I205>10000,"High value","Regular") -> Regular | M205: =_xlfn.XLOOKUP(A205,A:A,K:K,"Not Provided",0) -> Spain
A206: C648 | B206: Colleen Chapman | C206: 20 | D206: Male | E206: Married | F206: 45306 | G206: =TEXT(F206,"DDDD") -> Monday | H206: =TEXT(F206,"MMMM") -> January | I206: 44000 | J206: =IF(LEN(TRIM(I206))=0,"Not Recorded","Recorded") -> Recorded | K206: Not Provided | L206: =IF(I206>10000,"High value","Regular") -> High value | M206: =_xlfn.XLOOKUP(A206,A:A,K:K,"Not Provided",0) -> Not Provided
A207: C653 | B207: Stephen Mcconnell | C207: 30 | D207: Female | E207: Single | F207: 39104 | G207: =TEXT(F207,"DDDD") -> Monday | H207: =TEXT(F207,"MMMM") -> January | I207: 9500 | J207: =IF(LEN(TRIM(I207))=0,"Not Recorded","Recorded") -> Recorded | K207: Lagos | L207: =IF(I207>10000,"High value","Regular") -> Regular | M207: =_xlfn.XLOOKUP(A207,A:A,K:K,"Not Provided",0) -> Lagos
A208: C013 | B208: Jay Christensen | C208: 30 | D208: Male | E208: Single | F208: 43554 | G208: =TEXT(F208,"DDDD") -> Saturday | H208: =TEXT(F208,"MMMM") -> March | I208: 9500 | J208: =IF(LEN(TRIM(I208))=0,"Not Recorded","Recorded") -> Recorded | K208: Not Provided | L208: =IF(I208>10000,"High value","Regular") -> Regular | M208: =_xlfn.XLOOKUP(A208,A:A,K:K,"Not Provided",0) -> Not Provided
A209: C386 | B209: Erica Davis | C209: 37 | D209: Male | E209: Married | F209: 45502 | G209: =TEXT(F209,"DDDD") -> Monday | H209: =TEXT(F209,"MMMM") -> July | I209: 750 | J209: =IF(LEN(TRIM(I209))=0,"Not Recorded","Recorded") -> Recorded | K209: India | L209: =IF(I209>10000,"High value","Regular") -> Regular | M209: =_xlfn.XLOOKUP(A209,A:A,K:K,"Not Provided",0) -> India
A210: C730 | B210: Lisa Perry | C210: 64 | D210: Male | E210: Married | F210: 44819 | G210: =TEXT(F210,"DDDD") -> Thursday | H210: =TEXT(F210,"MMMM") -> September | I210: 1568.6056 | J210: =IF(LEN(TRIM(I210))=0,"Not Recorded","Recorded") -> Recorded | K210: India | L210: =IF(I210>10000,"High value","Regular") -> Regular | M210: =_xlfn.XLOOKUP(A210,A:A,K:K,"Not Provided",0) -> India
A211: C178 | B211: Richard Brennan | C211: 20 | D211: Male | E211: Married | F211: 45489 | G211: =TEXT(F211,"DDDD") -> Tuesday | H211: =TEXT(F211,"MMMM") -> July | I211: 6075.4086 | J211: =IF(LEN(TRIM(I211))=0,"Not Recorded","Recorded") -> Recorded | K211: Not Provided | L211: =IF(I211>10000,"High value","Regular") -> Regular | M211: =_xlfn.XLOOKUP(A211,A:A,K:K,"Not Provided",0) -> Not Provided
A212: C614 | B212: Wanda Grant | C212: 24 | D212: Male | E212: Married | F212: 43531 | G212: =TEXT(F212,"DDDD") -> Thursday | H212: =TEXT(F212,"MMMM") -> March | I212: 6708.792 | J212: =IF(LEN(TRIM(I212))=0,"Not Recorded","Recorded") -> Recorded | K212: Not Provided | L212: =IF(I212>10000,"High value","Regular") -> Regular | M212: =_xlfn.XLOOKUP(A212,A:A,K:K,"Not Provided",0) -> Not Provided
A213: C861 | B213: Julie Valdez | C213: 34 | D213: Female | E213: Single | F213: 45374 | G213: =TEXT(F213,"DDDD") -> Saturday | H213: =TEXT(F213,"MMMM") -> March | I213: 1500 | J213: =IF(LEN(TRIM(I213))=0,"Not Recorded","Recorded") -> Recorded | K213: Spain | L213: =IF(I213>10000,"High value","Regular") -> Regular | M213: =_xlfn.XLOOKUP(A213,A:A,K:K,"Not Provided",0) -> Spain
A214: C367 | B214: Victoria Dudley | C214: 20 | D214: Male | E214: Married | F214: 26696 | G214: =TEXT(F214,"DDDD") -> Thursday | H214: =TEXT(F214,"MMMM") -> February | I214: 15000 | J214: =IF(LEN(TRIM(I214))=0,"Not Recorded","Recorded") -> Recorded | K214: India | L214: =IF(I214>10000,"High value","Regular") -> High value | M214: =_xlfn.XLOOKUP(A214,A:A,K:K,"Not Provided",0) -> India
A215: C635 | B215: Janet Brown | C215: 43 | D215: Female | E215: Single | F215: 40803 | G215: =TEXT(F215,"DDDD") -> Saturday | H215: =TEXT(F215,"MMMM") -> September | I215: 6318.7943 | J215: =IF(LEN(TRIM(I215))=0,"Not Recorded","Recorded") -> Recorded | K215: Not Provided | L215: =IF(I215>10000,"High value","Regular") -> Regular | M215: =_xlfn.XLOOKUP(A215,A:A,K:K,"Not Provided",0) -> Not Provided
A216: C745 | B216: Albert Oconnor | C216: 20 | D216: Male | E216: Married | F216: 45501 | G216: =TEXT(F216,"DDDD") -> Sunday | H216: =TEXT(F216,"MMMM") -> July | I216: 7600 | J216: =IF(LEN(TRIM(I216))=0,"Not Recorded","Recorded") -> Recorded | K216: South Africa | L216: =IF(I216>10000,"High value","Regular") -> Regular | M216: =_xlfn.XLOOKUP(A216,A:A,K:K,"Not Provided",0) -> South Africa
A217: C843 | B217: Stephanie Brown | C217: 66 | D217: Male | E217: Single | F217: 38026 | G217: =TEXT(F217,"DDDD") -> Monday | H217: =TEXT(F217,"MMMM") -> February | I217: 7500 | J217: =IF(LEN(TRIM(I217))=0,"Not Recorded","Recorded") -> Recorded | K217: Not Provided | L217: =IF(I217>10000,"High value","Regular") -> Regular | M217: =_xlfn.XLOOKUP(A217,A:A,K:K,"Not Provided",0) -> Not Provided
... A237: C468 | B237: Michelle Wallace | C237: 20 | D237: Male | E237: Single | F237: 45305 | G237: =TEXT(F237,"DDDD") -> Sunday | H237: =TEXT(F237,"MMMM") -> January | I237: 9500 | J237: =IF(LEN(TRIM(I237))=0,"Not Recorded","Recorded") -> Recorded | K237: Lagos | L237: =IF(I237>10000,"High value","Regular") -> Regular | M237: =_xlfn.XLOOKUP(A237,A:A,K:K,"Not Provided",0) -> Lagos
A238: C176 | B238: Emma Lynch | C238: 20 | D238: Female | E238: Single | F238: 44138 | G238: =TEXT(F238,"DDDD") -> Tuesday | H238: =TEXT(F238,"MMMM") -> November | J238: =IF(LEN(TRIM(I238))=0,"Not Recorded","Recorded") -> Not Recorded | K238: Lagos | L238: =IF(I238>10000,"High value","Regular") -> Regular | M238: =_xlfn.XLOOKUP(A238,A:A,K:K,"Not Provided",0) -> Lagos
A239: C431 | B239: Dillon Ryan | C239: 30 | D239: Male | E239: Single | F239: 45437 | G239: =TEXT(F239,"DDDD") -> Saturday | H239: =TEXT(F239,"MMMM") -> May | I239: 9500 | J239: =IF(LEN(TRIM(I239))=0,"Not Recorded","Recorded") -> Recorded | K239: Not Provided | L239: =IF(I239>10000,"High value","Regular") -> Regular | M239: =_xlfn.XLOOKUP(A239,A:A,K:K,"Not Provided",0) -> Not Provided
A240: C404 | B240: Robert Moore | C240: 30 | D240: Male | E240: Single | F240: 36850 | G240: =TEXT(F240,"DDDD") -> Monday | H240: =TEXT(F240,"MMMM") -> November | I240: 9500 | J240: =IF(LEN(TRIM(I240))=0,"Not Recorded","Recorded") -> Recorded | K240: Not Provided | L240: =IF(I240>10000,"High value","Regular") -> Regular | M240: =_xlfn.XLOOKUP(A240,A:A,K:K,"Not Provided",0) -> Not Provided
A241: C070 | B241: Reginald Brown | C241: 47 | D241: Female | E241: Married | F241: 40456 | G241: =TEXT(F241,"DDDD") -> Tuesday | H241: =TEXT(F241,"MMMM") -> October | I241: 850 | J241: =IF(LEN(TRIM(I241))=0,"Not Recorded","Recorded") -> Recorded | K241: Lagos | L241: =IF(I241>10000,"High value","Regular") -> Regular | M241: =_xlfn.XLOOKUP(A241,A:A,K:K,"Not Provided",0) -> Lagos
A242: C206 | B242: Amanda Nelson | C242: 20 | D242: Male | E242: Single | F242: 44033 | G242: =TEXT(F242,"DDDD") -> Tuesday | H242: =TEXT(F242,"MMMM") -> July | I242: 1500 | J242: =IF(LEN(TRIM(I242))=0,"Not Recorded","Recorded") -> Recorded | K242: Lagos | L242: =IF(I242>10000,"High value","Regular") -> Regular | M242: =_xlfn.XLOOKUP(A242,A:A,K:K,"Not Provided",0) -> Lagos
...

Sheet Analysis Sheet
A1: Customer Count and Revenue Contribution by Location | F1: Monthly Revenue Trends | J1: Gender Based Analysis
A2: Location | B2: Number of Customers | C2: Revenue Contribution | F2: January | G2: =SUMIF('Cleaned Data'!H:H,'Analysis Sheet'!$F2,'Cleaned Data'!I:I) -> 322096.53 | J2: Gender | K2: Total Spenidng
A3: Lagos | B3: =COUNTIF('Cleaned Data'!K:K,$A3) -> 91 | C3: =SUMIF('Cleaned Data'!$K:$K,$A3,'Cleaned Data'!$I:$I) -> 601615.17 | F3: February | G3: =SUMIF('Cleaned Data'!H:H,'Analysis Sheet'!$F3,'Cleaned Data'!I:I) -> 286792.93 | J3: Male | K3: =SUMIF('Cleaned Data'!D:D,'Analysis Sheet'!$J3,'Cleaned Data'!I:I) -> 1498241.7
A4: Spain | B4: =COUNTIF('Cleaned Data'!K:K,$A4) -> 80 | C4: =SUMIF('Cleaned Data'!$K:$K,$A4,'Cleaned Data'!$I:$I) -> 468878.58 | F4: March | G4: =SUMIF('Cleaned Data'!H:H,'Analysis Sheet'!$F4,'Cleaned Data'!I:I) -> 183293.39 | J4: Female | K4: =SUMIF('Cleaned Data'!D:D,'Analysis Sheet'!$J4,'Cleaned Data'!I:I) -> 1310698.6
A5: India | B5: =COUNTIF('Cleaned Data'!K:K,$A5) -> 60 | C5: =SUMIF('Cleaned Data'!$K:$K,$A5,'Cleaned Data'!$I:$I) -> 329239.75 | F5: April | G5: =SUMIF('Cleaned Data'!H:H,'Analysis Sheet'!$F5,'Cleaned Data'!I:I) -> 316595.83
A6: South Africa | B6: =COUNTIF('Cleaned Data'!K:K,$A6) -> 68 | C6: =SUMIF('Cleaned Data'!$K:$K,$A6,'Cleaned Data'!$I:$I) -> 322588.36 | F6: May | G6: =SUMIF('Cleaned Data'!H:H,'Analysis Sheet'!$F6,'Cleaned Data'!I:I) -> 273687.49
A7: Total | B7: =SUM(B3:B6) -> 299 | C7: =SUM(C3:C6) -> 1722321.9 | F7: June | G7: =SUMIF('Cleaned Data'!H:H,'Analysis Sheet'!$F7,'Cleaned Data'!I:I) -> 212244.15
F8: July | G8: =SUMIF('Cleaned Data'!H:H,'Analysis Sheet'!$F8,'Cleaned Data'!I:I) -> 254748.31
F9: August | G9: =SUMIF('Cleaned Data'!H:H,'Analysis Sheet'!$F9,'Cleaned Data'!I:I) -> 295542.83
F10: September | G10: =SUMIF('Cleaned Data'!H:H,'Analysis Sheet'!$F10,'Cleaned Data'!I:I) -> 203770.43
A11: Gender-Based Revenue Analysis | F11: October | G11: =SUMIF('Cleaned Data'!H:H,'Analysis Sheet'!$F11,'Cleaned Data'!I:I) -> 102512.41
A12: Gender | B12: Total Spend ($) | C12: Average Spend($) | F12: November | G12: =SUMIF('Cleaned Data'!H:H,'Analysis Sheet'!$F12,'Cleaned Data'!I:I) -> 196744.17
A13: Male | B13: =SUMIF('Cleaned Data'!D:D,"Male",'Cleaned Data'!I:I) -> 1498241.7 | C13: =AVERAGEIF('Cleaned Data'!D:D,"Male",'Cleaned Data'!I:I) -> 6115.2723 | F13: December | G13: =SUMIF('Cleaned Data'!H:H,'Analysis Sheet'!$F13,'Cleaned Data'!I:I) -> 160911.8
A14: Female | B14: =SUMIF('Cleaned Data'!D:D,"Female",'Cleaned Data'!I:I) -> 1310698.6 | C14: =AVERAGEIF('Cleaned Data'!D:D,"Female",'Cleaned Data'!I:I) -> 5799.5512
A17: Marital Status Spending Behaviour
A18: Single | B18: =AVERAGEIF('Cleaned Data'!E:E,"Single",'Cleaned Data'!I:I) -> 6480.897 | F18: High value Transaction identification
A19: Married | B19: =AVERAGEIF('Cleaned Data'!E:E,"Married",'Cleaned Data'!I:I) -> 5393.5656 | F19: Regular | G19: =COUNTIF('Cleaned Data'!L:L,"Regular") -> 457
F20: High value | G20: =COUNTIF('Cleaned Data'!L:L,"High value") -> 24
A23: Revenue by Days of the Week
A24: Days of the Week | B24: Purchase Frequency | F24: Data completeness and quality review
A25: Monday | B25: =SUMIF('Cleaned Data'!G:G,'Analysis Sheet'!$A25,'Cleaned Data'!I:I) -> 489674.35 | F25: Location | G25: No of Customers
A26: Tuesday | B26: =SUMIF('Cleaned Data'!G:G,'Analysis Sheet'!$A26,'Cleaned Data'!I:I) -> 390792.52 | F26: India | G26: =COUNTIF('Cleaned Data'!K:K,'Analysis Sheet'!$F26) -> 60
A27: Wednesday | B27: =SUMIF('Cleaned Data'!G:G,'Analysis Sheet'!$A27,'Cleaned Data'!I:I) -> 347664.09 | F27: Lagos | G27: =COUNTIF('Cleaned Data'!K:K,'Analysis Sheet'!$F27) -> 91
A28: Thursday | B28: =SUMIF('Cleaned Data'!G:G,'Analysis Sheet'!$A28,'Cleaned Data'!I:I) -> 334101.11 | F28: South Africa | G28: =COUNTIF('Cleaned Data'!K:K,'Analysis Sheet'!$F28) -> 68
A29: Friday | B29: =SUMIF('Cleaned Data'!G:G,'Analysis Sheet'!$A29,'Cleaned Data'!I:I) -> 478467.13 | F29: Spain | G29: =COUNTIF('Cleaned Data'!K:K,'Analysis Sheet'!$F29) -> 80
A30: Saturday | B30: =SUMIF('Cleaned Data'!G:G,'Analysis Sheet'!$A30,'Cleaned Data'!I:I) -> 524784.17 | F30: Not Provided | G30: =COUNTIF('Cleaned Data'!K:K,'Analysis Sheet'!$F30) -> 182
A31: Sunday | B31: =SUMIF('Cleaned Data'!G:G,'Analysis Sheet'!$A31,'Cleaned Data'!I:I) -> 243456.9

Sheet Sheet7
A1: Days of the Week | B1: Frequency count
A2: Friday | B2: 84
A3: Monday | B3: 77
A4: Tuesday | B4: 75
A5: Thursday | B5: 69
A6: Saturday | B6: 69
A7: Sunday | B7: 64
A8: Wednesday | B8: 43

Sheet KPIS
A1: Name | B1: Amount
A2: Orge Sullivan | B2: 123000
A3: Holly Hall | B3: 120000
A4: Vanessa Fuentes | B4: 95000
A5: Sarah Sanchez | B5: 90000 | I5: Row Labels | J5: Sum of Amount
A6: Kathleen Marsh | B6: 78000 | I6: Orge Sullivan | J6: 123000
A7: Jason David | B7: 56000 | I7: Holly Hall | J7: 120000
A8: Keith Matthews | B8: 54000 | I8: Vanessa Fuentes | J8: 95000
A9: Richard Johnson | B9: 50000 | I9: Sarah Sanchez | J9: 90000
A10: Katie Mays | B10: 45000 | I10: Kathleen Marsh | J10: 78000
A11: Colleen Chapman | B11: 44000 | I11: Grand Total | J11: 506000
A12: Jeremy Wilson | B12: 34000
A13: Danielle Mckinney | B13: 29370
A14: Jennifer Silva | B14: 25000
A15: Desiree Landry | B15: 25000
A16: Scott Beard | B16: 23000
A17: Robert Martinez | B17: 18000
A18: Charles Ryan | B18: 17500
A19: Erica Hall | B19: 17000
A20: Nancy Roach | B20: 17000
A21: Victoria Dudley | B21: 15000
A22: Kimberly Schultz | B22: 14000
A23: Tina Curtis | B23: 13500
... A472: Marilyn Rodriguez | B472: 4.7349789
A473: Joshua Perry
A474: Emma Lynch
A475: Jose Copeland
A476: Jennifer Garcia
A477: Brent Johnson
A478: William King
A479: William King
A480: Desiree Landry
A481: Desiree Landry
A482: Desiree Landry

Sheet KPI's
A3: Location | B3: Sum of Amount
A4: Lagos | B4: 601615.17
A5: Spain | B5: 468878.58
A6: India | B6: 329239.75
A7: South Africa | B7: 322588.36
A12: Male | B12: SUMIF(#REF!,$P12,#REF!)
A13: Female | B13: =SUMIF(#REF!,$P13,#REF!) -> #REF!

Sheet Dashoards insights
A3: Location | B3: Count of Location
A4: Lagos | B4: 91
A5: Spain | B5: 80
A6: South Africa | B6: 68
A7: India | B7: 60

Sheet Dashboard

Sheet Sheet3
A3: Location | B3: Sum of Amount
A4: Not Provided | B4: 1086618.4
A5: Lagos | B5: 601615.17
A6: Spain | B6: 468878.58
A7: India | B7: 329239.75
A8: South Africa | B8: 322588.36

Sheet Sheet1
A1: Location | B1: Amount
A2: Lagos | B2: 123000
A3: Not Provided | B3: 120000 | E3: .
A4: Lagos | B4: 95000
A5: Not Provided | B5: 90000
A6: Spain | B6: 78000
A7: Not Provided | B7: 56000
A8: India | B8: 54000 | E8: Not Provided | F8: =SUMIF(A:A,E8,B:B) -> 1086618.4
A9: Spain | B9: 50000
A10: Not Provided | B10: 45000
A11: Not Provided | B11: 44000
A12: Lagos | B12: 34000
A13: India | B13: 29370
A14: Lagos | B14: 25000
A15: Not Provided | B15: 25000
A16: South Africa | B16: 23000
A17: South Africa | B17: 18000
A18: Spain | B18: 17500
A19: South Africa | B19: 17000
A20: Not Provided | B20: 17000
... A472: Lagos | B472: 4.7349789
A473: Not Provided
A474: Lagos
A475: Not Provided
A476: Spain
A477: Not Provided
A478: India
A479: South Africa
A480: Not Provided
A481: India
A482: India
